Traceback (most recent call last):
  File "/usr/local/lib/python3.10/site-packages/jupyter_cache/executors/utils.py", line 51, in single_nb_execution
    executenb(
  File "/usr/local/lib/python3.10/site-packages/nbclient/client.py", line 1204, in execute
    return NotebookClient(nb=nb, resources=resources, km=km, **kwargs).execute()
  File "/usr/local/lib/python3.10/site-packages/nbclient/util.py", line 84, in wrapped
    return just_run(coro(*args, **kwargs))
  File "/usr/local/lib/python3.10/site-packages/nbclient/util.py", line 62, in just_run
    return loop.run_until_complete(coro)
  File "/usr/local/Cellar/python@3.10/3.10.6_1/Frameworks/Python.framework/Versions/3.10/lib/python3.10/asyncio/base_events.py", line 646, in run_until_complete
    return future.result()
  File "/usr/local/lib/python3.10/site-packages/nbclient/client.py", line 663, in async_execute
    await self.async_execute_cell(
  File "/usr/local/lib/python3.10/site-packages/nbclient/client.py", line 965, in async_execute_cell
    await self._check_raise_for_error(cell, cell_index, exec_reply)
  File "/usr/local/lib/python3.10/site-packages/nbclient/client.py", line 862, in _check_raise_for_error
    raise CellExecutionError.from_cell_and_msg(cell, exec_reply_content)
nbclient.exceptions.CellExecutionError: An error occurred while executing the following cell:
------------------
model.graph.plot_prediction(X_test, y_test)
plt.show()
------------------

[0;31m---------------------------------------------------------------------------[0m
[0;31mIndexError[0m                                Traceback (most recent call last)
Input [0;32mIn [32][0m, in [0;36m<cell line: 1>[0;34m()[0m
[0;32m----> 1[0m [43mmodel[49m[38;5;241;43m.[39;49m[43mgraph[49m[38;5;241m.[39mplot_prediction(X_test, y_test)
[1;32m      2[0m plt[38;5;241m.[39mshow()

File [0;32m/usr/local/lib/python3.10/site-packages/sandbox-0.0.0-py3.10.egg/sandbox/graphics/ts_grapher.py:296[0m, in [0;36mTimeSeriesGrapherMixin.graph[0;34m(self)[0m
[1;32m    294[0m [38;5;129m@property[39m
[1;32m    295[0m [38;5;28;01mdef[39;00m [38;5;21mgraph[39m([38;5;28mself[39m):
[0;32m--> 296[0m     [38;5;28;01mreturn[39;00m [43mTimeSeriesGrapher[49m[43m([49m[38;5;28;43mself[39;49m[43m)[49m

File [0;32m/usr/local/lib/python3.10/site-packages/sandbox-0.0.0-py3.10.egg/sandbox/graphics/ts_grapher.py:20[0m, in [0;36mTimeSeriesGrapher.__init__[0;34m(self, model)[0m
[1;32m     16[0m [38;5;28;01mdef[39;00m [38;5;21m__init__[39m([38;5;28mself[39m, model):
[1;32m     17[0m     [38;5;28mself[39m[38;5;241m.[39mmodel [38;5;241m=[39m model
[1;32m     18[0m     [38;5;28;01mif[39;00m (
[1;32m     19[0m         [38;5;28mself[39m[38;5;241m.[39mmodel[38;5;241m.[39mdata_[38;5;241m.[39my[38;5;241m.[39mvalues[38;5;241m.[39mshape[[38;5;241m0[39m] [38;5;241m>[39m [38;5;241m1[39m
[0;32m---> 20[0m         [38;5;129;01mand[39;00m [38;5;28;43mself[39;49m[38;5;241;43m.[39;49m[43mmodel[49m[38;5;241;43m.[39;49m[43mdata_[49m[38;5;241;43m.[39;49m[43my[49m[38;5;241;43m.[39;49m[43mvalues[49m[38;5;241;43m.[39;49m[43mshape[49m[43m[[49m[38;5;241;43m1[39;49m[43m][49m [38;5;241m>[39m [38;5;241m1[39m
[1;32m     21[0m     ):
[1;32m     22[0m         msg [38;5;241m=[39m [38;5;124m"[39m[38;5;124mThe module supports only univariate modeling.[39m[38;5;124m"[39m
[1;32m     23[0m         [38;5;28;01mraise[39;00m [38;5;167;01mNotImplementedError[39;00m(msg)

[0;31mIndexError[0m: tuple index out of range
IndexError: tuple index out of range

